<?xml version="1.0"?>
<robot name="mining_robot">
    <!-- Base Link (Main Chassis) -->
    <link name="base_link">
        <visual>
            <geometry>
                <box size="0.8 0.6 0.2"/>
            </geometry>
            <material name="gray">
                <color rgba="0.5 0.5 0.5 1"/>
            </material>
        </visual>
        <collision>
            <geometry>
                <box size="0.8 0.6 0.2"/>
            </geometry>
        </collision>
        <inertial>
            <mass value="50.0"/>
            <inertia ixx="1.0" ixy="0.0" ixz="0.0" iyy="1.0" iyz="0.0" izz="1.0"/>
        </inertial>
    </link>

    <!-- Electronics Box -->
    <link name="electronics_box">
        <visual>
            <geometry>
                <box size="0.3 0.4 0.3"/>
            </geometry>
            <material name="dark_gray">
                <color rgba="0.3 0.3 0.3 1"/>
            </material>
        </visual>
        <collision>
            <geometry>
                <box size="0.3 0.4 0.3"/>
            </geometry>
        </collision>
        <inertial>
            <mass value="5.0"/>
            <inertia ixx="0.1" ixy="0.0" ixz="0.0" iyy="0.1" iyz="0.0" izz="0.1"/>
        </inertial>
    </link>

    <!-- Electronics Box Joint -->
    <joint name="electronics_box_joint" type="fixed">
        <parent link="base_link"/>
        <child link="electronics_box"/>
        <origin xyz="0 0 0.25" rpy="0 0 0"/>
    </joint>

    <!-- Wheels -->
    <link name="left_wheel">
        <visual>
            <geometry>
                <cylinder radius="0.127" length="0.1"/>
            </geometry>
            <material name="black">
                <color rgba="0.1 0.1 0.1 1"/>
            </material>
        </visual>
        <collision>
            <geometry>
                <cylinder radius="0.127" length="0.1"/>
            </geometry>
        </collision>
        <inertial>
            <mass value="5.0"/>
            <inertia ixx="0.1" ixy="0.0" ixz="0.0" iyy="0.1" iyz="0.0" izz="0.1"/>
        </inertial>
    </link>

    <link name="right_wheel">
        <visual>
            <geometry>
                <cylinder radius="0.127" length="0.1"/>
            </geometry>
            <material name="black"/>
        </visual>
        <collision>
            <geometry>
                <cylinder radius="0.127" length="0.1"/>
            </geometry>
        </collision>
        <inertial>
            <mass value="5.0"/>
            <inertia ixx="0.1" ixy="0.0" ixz="0.0" iyy="0.1" iyz="0.0" izz="0.1"/>
        </inertial>
    </link>

    <!-- Wheel Joints -->
    <joint name="left_wheel_joint" type="continuous">
        <parent link="base_link"/>
        <child link="left_wheel"/>
        <origin xyz="0 0.35 0" rpy="-1.5708 0 0"/>
        <axis xyz="0 0 1"/>
    </joint>

    <joint name="right_wheel_joint" type="continuous">
        <parent link="base_link"/>
        <child link="right_wheel"/>
        <origin xyz="0 -0.35 0" rpy="-1.5708 0 0"/>
        <axis xyz="0 0 1"/>
    </joint>

    <!-- Conveyor System -->
    <link name="conveyor">
        <visual>
            <geometry>
                <box size="1.0 0.4 0.1"/>
            </geometry>
            <material name="red">
                <color rgba="0.8 0.0 0.0 1"/>
            </material>
        </visual>
        <collision>
            <geometry>
                <box size="1.0 0.4 0.1"/>
            </geometry>
        </collision>
        <inertial>
            <mass value="10.0"/>
            <inertia ixx="0.1" ixy="0.0" ixz="0.0" iyy="0.1" iyz="0.0" izz="0.1"/>
        </inertial>
    </link>

    <!-- Conveyor Joint -->
    <joint name="conveyor_joint" type="revolute">
        <parent link="base_link"/>
        <child link="conveyor"/>
        <origin xyz="0.4 0 0.4" rpy="0 0.7854 0"/>
        <axis xyz="0 1 0"/>
        <limit lower="-1.5708" upper="1.5708" effort="100" velocity="1.0"/>
    </joint>
    
    <!-- Gazebo plugin for differential drive -->
    <gazebo>
        <plugin name="differential_drive_controller" filename="libgazebo_ros_diff_drive.so">
            <leftJoint>left_wheel_joint</leftJoint>
            <rightJoint>right_wheel_joint</rightJoint>
            <wheelSeparation>0.7</wheelSeparation>
            <wheelDiameter>0.254</wheelDiameter>
            <robotBaseFrame>base_link</robotBaseFrame>
            <publishWheelTF>true</publishWheelTF>
            <publishWheelJointState>true</publishWheelJointState>
            <wheelAcceleration>1.0</wheelAcceleration>
            <wheelTorque>20</wheelTorque>
            <odometryFrame>odom</odometryFrame>
            <commandTopic>cmd_vel</commandTopic>
            <odometryTopic>odom</odometryTopic>
            <odometrySource>world</odometrySource>
            <publishOdomTF>true</publishOdomTF>
        </plugin>
    </gazebo>

    <gazebo>
    <plugin name="gazebo_ros2_control" filename="libgazebo_ros2_control.so">
        <parameters>$(find robot_description)/config/controller_config.yaml</parameters>
    </plugin>
    </gazebo>

</robot>